# try catch

try:
    open
except:
    print(“Erro”)
else:
    print(“Sucesso”)